<?xml version="1.0" encoding="utf-8"?>
<!-- This URDF was automatically created by SolidWorks to URDF Exporter! Originally created by Stephen Brawner (brawner@gmail.com) 
     Commit Version: 1.6.0-1-g15f4949  Build Version: 1.6.7594.29634
     For more information, please see http://wiki.ros.org/sw_urdf_exporter -->
<robot
  name="Wheelchair_urdf">
  <link
    name="base_link">
    <inertial>
      <origin
        xyz="-0.1407 -0.006319 -0.18101"
        rpy="0 0 0" />
      <mass
        value="41.21" />
      <inertia
        ixx="6.3763"
        ixy="0.00016929"
        ixz="-0.65901"
        iyy="6.701"
        iyz="0.0001018"
        izz="6.3533" />
    </inertial>
    <visual>
      <origin
        xyz="0 0 0"
        rpy="0 0 0" />
      <geometry>
        <mesh
          filename="package://Wheelchair_urdf/meshes/base_link.STL" />
      </geometry>
      <material
        name="">
        <color
          rgba="0.62745 0.62745 0.62745 1" />
      </material>
    </visual>
    <collision>
      <origin
        xyz="0 0 0"
        rpy="0 0 0" />
      <geometry>
        <mesh
          filename="package://Wheelchair_urdf/meshes/base_link.STL" />
      </geometry>
    </collision>
  </link>
  <link
    name="lidar_r">
    <inertial>
      <origin
        xyz="0 0 -0.015"
        rpy="0 0 0" />
      <mass
        value="0.028863" />
      <inertia
        ixx="4.3746E-06"
        ixy="0"
        ixz="0"
        iyy="4.3746E-06"
        iyz="-1.4642E-38"
        izz="4.4197E-06" />
    </inertial>
    <visual>
      <origin
        xyz="0 0 0"
        rpy="0 0 0" />
      <geometry>
        <mesh
          filename="package://Wheelchair_urdf/meshes/lidar_r.STL" />
      </geometry>
      <material
        name="">
        <color
          rgba="0.75294 0.75294 0.75294 1" />
      </material>
    </visual>
    <collision>
      <origin
        xyz="0 0 0"
        rpy="0 0 0" />
      <geometry>
        <mesh
          filename="package://Wheelchair_urdf/meshes/lidar_r.STL" />
      </geometry>
    </collision>
  </link>
  <joint
    name="lidar_r_joint"
    type="fixed">
    <origin
      xyz="0.53347 -0.30933 -0.3995"
      rpy="0 0 0" />
    <parent
      link="base_link" />
    <child
      link="lidar_r" />
    <axis
      xyz="0 0 0" />
  </joint>
  <link
    name="lidar_l">
    <inertial>
      <origin
        xyz="0 -1.1102E-16 -0.015"
        rpy="0 0 0" />
      <mass
        value="0.028863" />
      <inertia
        ixx="4.3746E-06"
        ixy="0"
        ixz="0"
        iyy="4.3746E-06"
        iyz="-1.4642E-38"
        izz="4.4197E-06" />
    </inertial>
    <visual>
      <origin
        xyz="0 0 0"
        rpy="0 0 0" />
      <geometry>
        <mesh
          filename="package://Wheelchair_urdf/meshes/lidar_l.STL" />
      </geometry>
      <material
        name="">
        <color
          rgba="0.75294 0.75294 0.75294 1" />
      </material>
    </visual>
    <collision>
      <origin
        xyz="0 0 0"
        rpy="0 0 0" />
      <geometry>
        <mesh
          filename="package://Wheelchair_urdf/meshes/lidar_l.STL" />
      </geometry>
    </collision>
  </link>
  <joint
    name="lidar_l_joint"
    type="fixed">
    <origin
      xyz="0.53347 0.30688 -0.3995"
      rpy="0 0 0" />
    <parent
      link="base_link" />
    <child
      link="lidar_l" />
    <axis
      xyz="0 0 0" />
  </joint>
  <link
    name="lidar_t">
    <inertial>
      <origin
        xyz="0 0 -0.015"
        rpy="0 0 0" />
      <mass
        value="0.028863" />
      <inertia
        ixx="4.3746E-06"
        ixy="-1.4987E-22"
        ixz="-1.9058E-21"
        iyy="4.3746E-06"
        iyz="4.5539E-23"
        izz="4.4197E-06" />
    </inertial>
    <visual>
      <origin
        xyz="0 0 0"
        rpy="0 0 0" />
      <geometry>
        <mesh
          filename="package://Wheelchair_urdf/meshes/lidar_t.STL" />
      </geometry>
      <material
        name="">
        <color
          rgba="0.75294 0.75294 0.75294 1" />
      </material>
    </visual>
    <collision>
      <origin
        xyz="0 0 0"
        rpy="0 0 0" />
      <geometry>
        <mesh
          filename="package://Wheelchair_urdf/meshes/lidar_t.STL" />
      </geometry>
    </collision>
  </link>
  <joint
    name="lidar_t_joint"
    type="fixed">
    <origin
      xyz="-0.47298 0 0.81687"
      rpy="0 -0.10674 0" />
    <parent
      link="base_link" />
    <child
      link="lidar_t" />
    <axis
      xyz="0 0 0" />
  </joint>
  <link
    name="lf_2">
    <inertial>
      <origin
        xyz="-0.012808 -0.024701 -0.072666"
        rpy="0 0 0" />
      <mass
        value="0.23831" />
      <inertia
        ixx="0.0011666"
        ixy="-1.5828E-05"
        ixz="-0.00017342"
        iyy="0.001149"
        iyz="-0.00010181"
        izz="0.00022446" />
    </inertial>
    <visual>
      <origin
        xyz="0 0 0"
        rpy="0 0 0" />
      <geometry>
        <mesh
          filename="package://Wheelchair_urdf/meshes/lf_2.STL" />
      </geometry>
      <material
        name="">
        <color
          rgba="0.62745 0.62745 0.62745 1" />
      </material>
    </visual>
    <collision>
      <origin
        xyz="0 0 0"
        rpy="0 0 0" />
      <geometry>
        <mesh
          filename="package://Wheelchair_urdf/meshes/lf_2.STL" />
      </geometry>
    </collision>
  </link>
  <joint
    name="lf_2_joint"
    type="continuous">
    <origin
      xyz="0.32552 0.38188 -0.5095"
      rpy="0 0 3.1416" />
    <parent
      link="base_link" />
    <child
      link="lf_2" />
    <axis
      xyz="0 0 -1" />
  </joint>
  <link
    name="lf_1">
    <inertial>
      <origin
        xyz="2.721E-10 -5.0624E-12 0.033"
        rpy="0 0 0" />
      <mass
        value="0.67334" />
      <inertia
        ixx="0.0033331"
        ixy="1.8117E-13"
        ixz="1.8328E-13"
        iyy="0.0033331"
        iyz="-3.4356E-13"
        izz="0.0065825" />
    </inertial>
    <visual>
      <origin
        xyz="0 0 0"
        rpy="0 0 0" />
      <geometry>
        <mesh
          filename="package://Wheelchair_urdf/meshes/lf_1.STL" />
      </geometry>
      <material
        name="">
        <color
          rgba="0.62745 0.62745 0.62745 1" />
      </material>
    </visual>
    <collision>
      <origin
        xyz="0 0 0"
        rpy="0 0 0" />
      <geometry>
        <mesh
          filename="package://Wheelchair_urdf/meshes/lf_1.STL" />
      </geometry>
    </collision>
  </link>
  <joint
    name="lf_1_joint"
    type="continuous">
    <origin
      xyz="-0.024949 0.0295 -0.14149"
      rpy="-1.5708 0 3.1416" />
    <parent
      link="lf_2" />
    <child
      link="lf_1" />
    <axis
      xyz="0 0 1" />
  </joint>
  <link
    name="rf_2">
    <inertial>
      <origin
        xyz="0.012808 -0.024701 -0.072666"
        rpy="0 0 0" />
      <mass
        value="0.23831" />
      <inertia
        ixx="0.0011666"
        ixy="1.5828E-05"
        ixz="0.00017342"
        iyy="0.001149"
        iyz="-0.00010181"
        izz="0.00022446" />
    </inertial>
    <visual>
      <origin
        xyz="0 0 0"
        rpy="0 0 0" />
      <geometry>
        <mesh
          filename="package://Wheelchair_urdf/meshes/rf_2.STL" />
      </geometry>
      <material
        name="">
        <color
          rgba="0.62745 0.62745 0.62745 1" />
      </material>
    </visual>
    <collision>
      <origin
        xyz="0 0 0"
        rpy="0 0 0" />
      <geometry>
        <mesh
          filename="package://Wheelchair_urdf/meshes/rf_2.STL" />
      </geometry>
    </collision>
  </link>
  <joint
    name="rf_2_joint"
    type="continuous">
    <origin
      xyz="0.32552 -0.38188 -0.5095"
      rpy="0 0 0" />
    <parent
      link="base_link" />
    <child
      link="rf_2" />
    <axis
      xyz="0 0 -1" />
  </joint>
  <link
    name="rf_1">
    <inertial>
      <origin
        xyz="3.0616E-10 6.0731E-11 -0.033"
        rpy="0 0 0" />
      <mass
        value="0.67334" />
      <inertia
        ixx="0.0033331"
        ixy="2.5865E-12"
        ixz="2.4846E-12"
        iyy="0.0033331"
        iyz="7.8731E-13"
        izz="0.0065825" />
    </inertial>
    <visual>
      <origin
        xyz="0 0 0"
        rpy="0 0 0" />
      <geometry>
        <mesh
          filename="package://Wheelchair_urdf/meshes/rf_1.STL" />
      </geometry>
      <material
        name="">
        <color
          rgba="0.62745 0.62745 0.62745 1" />
      </material>
    </visual>
    <collision>
      <origin
        xyz="0 0 0"
        rpy="0 0 0" />
      <geometry>
        <mesh
          filename="package://Wheelchair_urdf/meshes/rf_1.STL" />
      </geometry>
    </collision>
  </link>
  <joint
    name="rf_1_joint"
    type="continuous">
    <origin
      xyz="0.024949 0.0295 -0.14149"
      rpy="-1.5708 0 0" />
    <parent
      link="rf_2" />
    <child
      link="rf_1" />
    <axis
      xyz="0 0 1" />
  </joint>
  <link
    name="rb_1">
    <inertial>
      <origin
        xyz="2.9846E-09 1.1851E-09 0.060456"
        rpy="0 0 0" />
      <mass
        value="6.8929" />
      <inertia
        ixx="0.051089"
        ixy="2.9975E-11"
        ixz="1.9576E-10"
        iyy="0.051089"
        iyz="4.6179E-11"
        izz="0.093148" />
    </inertial>
    <visual>
      <origin
        xyz="0 0 0"
        rpy="0 0 0" />
      <geometry>
        <mesh
          filename="package://Wheelchair_urdf/meshes/rb_1.STL" />
      </geometry>
      <material
        name="">
        <color
          rgba="0.62745 0.62745 0.62745 1" />
      </material>
    </visual>
    <collision>
      <origin
        xyz="0 0 0"
        rpy="0 0 0" />
      <geometry>
        <mesh
          filename="package://Wheelchair_urdf/meshes/rb_1.STL" />
      </geometry>
    </collision>
  </link>
  <joint
    name="rb_1_joint"
    type="continuous">
    <origin
      xyz="-0.50545 -0.47488 -0.56973"
      rpy="-1.5708 0 0" />
    <parent
      link="base_link" />
    <child
      link="rb_1" />
    <axis
      xyz="0 0 1" />
  </joint>
  <link
    name="lb_1">
    <inertial>
      <origin
        xyz="0 0 0"
        rpy="0 0 0" />
      <mass
        value="0" />
      <inertia
        ixx="0"
        ixy="0"
        ixz="0"
        iyy="0"
        iyz="0"
        izz="0" />
    </inertial>
    <visual>
      <origin
        xyz="0 0 0"
        rpy="0 0 0" />
      <geometry>
        <mesh
          filename="package://Wheelchair_urdf/meshes/lb_1.STL" />
      </geometry>
      <material
        name="">
        <color
          rgba="1 1 1 1" />
      </material>
    </visual>
    <collision>
      <origin
        xyz="0 0 0"
        rpy="0 0 0" />
      <geometry>
        <mesh
          filename="package://Wheelchair_urdf/meshes/lb_1.STL" />
      </geometry>
    </collision>
  </link>
  <joint
    name="lb_1_joint"
    type="continuous">
    <origin
      xyz="-0.50545 0.47488 -0.56973"
      rpy="-1.5708 0 0" />
    <parent
      link="base_link" />
    <child
      link="lb_1" />
    <axis
      xyz="0 0 1" />
  </joint>
</robot>