<?xml version="1.0" encoding="utf-8"?>
<!-- This URDF was automatically created by SolidWorks to URDF Exporter! Originally created by Stephen Brawner (brawner@gmail.com) 
     Commit Version: 1.6.0-1-g15f4949  Build Version: 1.6.7594.29634
     For more information, please see http://wiki.ros.org/sw_urdf_exporter -->
<robot
  name="Wheelchair_v4">
  <link
    name="base_link">
    <inertial>
      <origin
        xyz="0.182408525440924 -0.00312331080687833 0.191583224757413"
        rpy="0 0 0" />
      <mass
        value="5.19146797116347" />
      <inertia
        ixx="0.201965980400546"
        ixy="5.39982512291012E-06"
        ixz="-0.0219181056816365"
        iyy="0.212071755125648"
        iyz="3.18564452654107E-06"
        izz="0.200544667219791" />
    </inertial>
    <visual>
      <origin
        xyz="0 0 0"
        rpy="0 0 0" />
      <geometry>
        <mesh
          filename="package://Wheelchair_v4/meshes/base_link.STL" />
      </geometry>
      <material
        name="">
        <color
          rgba="0.627450980392157 0.627450980392157 0.627450980392157 1" />
      </material>
    </visual>
    <collision>
      <origin
        xyz="0 0 0"
        rpy="0 0 0" />
      <geometry>
        <mesh
          filename="package://Wheelchair_v4/meshes/base_link.STL" />
      </geometry>
    </collision>
  </link>
  <link
    name="lidar_l">
    <inertial>
      <origin
        xyz="0 1.11022302462516E-16 -0.00499999999999995"
        rpy="0 0 0" />
      <mass
        value="0.00113097335529233" />
      <inertia
        ixx="1.96035381584004E-08"
        ixy="-8.89219158494505E-24"
        ixz="-1.79366203433577E-41"
        iyy="1.96035381584003E-08"
        iyz="4.41162993361615E-24"
        izz="2.03575203952619E-08" />
    </inertial>
    <visual>
      <origin
        xyz="0 0 0"
        rpy="0 0 0" />
      <geometry>
        <mesh
          filename="package://Wheelchair_v4/meshes/lidar_l.STL" />
      </geometry>
      <material
        name="">
        <color
          rgba="0.627450980392157 0.627450980392157 0.627450980392157 1" />
      </material>
    </visual>
    <collision>
      <origin
        xyz="0 0 0"
        rpy="0 0 0" />
      <geometry>
        <mesh
          filename="package://Wheelchair_v4/meshes/lidar_l.STL" />
      </geometry>
    </collision>
  </link>
  <joint
    name="lidar_l_joint"
    type="fixed">
    <origin
      xyz="0.51234 0.27982 0.084114"
      rpy="0 0 0" />
    <parent
      link="base_link" />
    <child
      link="lidar_l" />
    <axis
      xyz="0 0 0" />
  </joint>
  <link
    name="lidar_r">
    <inertial>
      <origin
        xyz="0 0 -0.00499999999999995"
        rpy="0 0 0" />
      <mass
        value="0.00113097335529233" />
      <inertia
        ixx="1.96035381584004E-08"
        ixy="8.96112330265781E-24"
        ixz="4.80455455349343E-40"
        iyy="1.96035381584003E-08"
        iyz="0"
        izz="2.03575203952619E-08" />
    </inertial>
    <visual>
      <origin
        xyz="0 0 0"
        rpy="0 0 0" />
      <geometry>
        <mesh
          filename="package://Wheelchair_v4/meshes/lidar_r.STL" />
      </geometry>
      <material
        name="">
        <color
          rgba="0.627450980392157 0.627450980392157 0.627450980392157 1" />
      </material>
    </visual>
    <collision>
      <origin
        xyz="0 0 0"
        rpy="0 0 0" />
      <geometry>
        <mesh
          filename="package://Wheelchair_v4/meshes/lidar_r.STL" />
      </geometry>
    </collision>
  </link>
  <joint
    name="lidar_r_joint"
    type="fixed">
    <origin
      xyz="0.51152 -0.27693 0.084114"
      rpy="0 0 0" />
    <parent
      link="base_link" />
    <child
      link="lidar_r" />
    <axis
      xyz="0 0 0" />
  </joint>
  <link
    name="lidar_t">
    <inertial>
      <origin
        xyz="-1.72605643738999E-06 1.24806954215906E-06 -0.00749999999999995"
        rpy="0 0 0" />
      <mass
        value="0.00314212358474844" />
      <inertia
        ixx="1.68261286200528E-07"
        ixy="2.64253299585466E-13"
        ixz="3.70597095544191E-22"
        iyy="1.68080790319748E-07"
        iyz="8.90021843646033E-14"
        izz="2.18512428853231E-07" />
    </inertial>
    <visual>
      <origin
        xyz="0 0 0"
        rpy="0 0 0" />
      <geometry>
        <mesh
          filename="package://Wheelchair_v4/meshes/lidar_t.STL" />
      </geometry>
      <material
        name="">
        <color
          rgba="0.627450980392157 0.627450980392157 0.627450980392157 1" />
      </material>
    </visual>
    <collision>
      <origin
        xyz="0 0 0"
        rpy="0 0 0" />
      <geometry>
        <mesh
          filename="package://Wheelchair_v4/meshes/lidar_t.STL" />
      </geometry>
    </collision>
  </link>
  <joint
    name="lidar_t_joint"
    type="fixed">
    <origin
      xyz="0.020807 0 0.66565"
      rpy="0 0 0" />
    <parent
      link="base_link" />
    <child
      link="lidar_t" />
    <axis
      xyz="0 0 0" />
  </joint>
  <link
    name="rb_1">
    <inertial>
      <origin
        xyz="1.9776E-09 -6.144E-10 0.030228"
        rpy="0 0 0" />
      <mass
        value="0.86161" />
      <inertia
        ixx="0.0015965"
        ixy="1.7582E-12"
        ixz="2.8243E-11"
        iyy="0.0015965"
        iyz="-1.075E-11"
        izz="0.0029109" />
    </inertial>
    <visual>
      <origin
        xyz="0 0 0"
        rpy="0 0 0" />
      <geometry>
        <mesh
          filename="package://Wheelchair_v4/meshes/rb_1.STL" />
      </geometry>
      <material
        name="">
        <color
          rgba="0.62745 0.62745 0.62745 1" />
      </material>
    </visual>
    <collision>
      <origin
        xyz="0 0 0"
        rpy="0 0 0" />
      <geometry>
        <mesh
          filename="package://Wheelchair_v4/meshes/rb_1.STL" />
      </geometry>
    </collision>
  </link>
  <joint
    name="rb_1_joint"
    type="continuous">
    <origin
      xyz="-6.4083E-05 -0.23244 -0.018015"
      rpy="-1.5708 0 0" />
    <parent
      link="base_link" />
    <child
      link="rb_1" />
    <axis
      xyz="0 0 1" />
  </joint>
  <link
    name="lb_1">
    <inertial>
      <origin
        xyz="-1.0317E-10 2.0094E-10 -0.030229"
        rpy="0 0 0" />
      <mass
        value="0.86162" />
      <inertia
        ixx="0.001596"
        ixy="7.781E-12"
        ixz="-5.1392E-13"
        iyy="0.001596"
        iyz="-2.4587E-12"
        izz="0.0029098" />
    </inertial>
    <visual>
      <origin
        xyz="0 0 0"
        rpy="0 0 0" />
      <geometry>
        <mesh
          filename="package://Wheelchair_v4/meshes/lb_1.STL" />
      </geometry>
      <material
        name="">
        <color
          rgba="0.62745 0.62745 0.62745 1" />
      </material>
    </visual>
    <collision>
      <origin
        xyz="0 0 0"
        rpy="0 0 0" />
      <geometry>
        <mesh
          filename="package://Wheelchair_v4/meshes/lb_1.STL" />
      </geometry>
    </collision>
  </link>
  <joint
    name="lb_1_joint"
    type="continuous">
    <origin
      xyz="-6.4083E-05 0.23244 -0.018015"
      rpy="-1.5708 0 0" />
    <parent
      link="base_link" />
    <child
      link="lb_1" />
    <axis
      xyz="0 0 1" />
  </joint>
  <link
    name="lf_2">
    <inertial>
      <origin
        xyz="-0.006404 0.012351 0.036333"
        rpy="0 0 0" />
      <mass
        value="0.029788" />
      <inertia
        ixx="3.6455E-05"
        ixy="4.9462E-07"
        ixz="5.4193E-06"
        iyy="3.5906E-05"
        iyz="-3.1816E-06"
        izz="7.0144E-06" />
    </inertial>
    <visual>
      <origin
        xyz="0 0 0"
        rpy="0 0 0" />
      <geometry>
        <mesh
          filename="package://Wheelchair_v4/meshes/lf_2.STL" />
      </geometry>
      <material
        name="">
        <color
          rgba="0.62745 0.62745 0.62745 1" />
      </material>
    </visual>
    <collision>
      <origin
        xyz="0 0 0"
        rpy="0 0 0" />
      <geometry>
        <mesh
          filename="package://Wheelchair_v4/meshes/lf_2.STL" />
      </geometry>
    </collision>
  </link>
  <joint
    name="lf_2_joint"
    type="continuous">
    <origin
      xyz="0.41548 0.19094 0.030114"
      rpy="3.1416 0 3.1416" />
    <parent
      link="base_link" />
    <child
      link="lf_2" />
    <axis
      xyz="0 0 1" />
  </joint>
  <link
    name="lf_1">
    <inertial>
      <origin
        xyz="1.3605E-10 -2.5313E-12 0.0165"
        rpy="0 0 0" />
      <mass
        value="0.084167" />
      <inertia
        ixx="0.00010416"
        ixy="5.6617E-15"
        ixz="5.7277E-15"
        iyy="0.00010416"
        iyz="-1.0736E-14"
        izz="0.0002057" />
    </inertial>
    <visual>
      <origin
        xyz="0 0 0"
        rpy="0 0 0" />
      <geometry>
        <mesh
          filename="package://Wheelchair_v4/meshes/lf_1.STL" />
      </geometry>
      <material
        name="">
        <color
          rgba="0.62745 0.62745 0.62745 1" />
      </material>
    </visual>
    <collision>
      <origin
        xyz="0 0 0"
        rpy="0 0 0" />
      <geometry>
        <mesh
          filename="package://Wheelchair_v4/meshes/lf_1.STL" />
      </geometry>
    </collision>
  </link>
  <joint
    name="lf_1_joint"
    type="continuous">
    <origin
      xyz="-0.012474 -0.01475 0.070746"
      rpy="1.5708 0 3.1416" />
    <parent
      link="lf_2" />
    <child
      link="lf_1" />
    <axis
      xyz="0 0 1" />
  </joint>
  <link
    name="rf_2">
    <inertial>
      <origin
        xyz="-0.0063204 0.010601 0.036333"
        rpy="0 0 0" />
      <mass
        value="0.029788" />
      <inertia
        ixx="3.6455E-05"
        ixy="-4.9462E-07"
        ixz="-5.4193E-06"
        iyy="3.5906E-05"
        iyz="-3.1816E-06"
        izz="7.0144E-06" />
    </inertial>
    <visual>
      <origin
        xyz="0 0 0"
        rpy="0 0 0" />
      <geometry>
        <mesh
          filename="package://Wheelchair_v4/meshes/rf_2.STL" />
      </geometry>
      <material
        name="">
        <color
          rgba="0.62745 0.62745 0.62745 1" />
      </material>
    </visual>
    <collision>
      <origin
        xyz="0 0 0"
        rpy="0 0 0" />
      <geometry>
        <mesh
          filename="package://Wheelchair_v4/meshes/rf_2.STL" />
      </geometry>
    </collision>
  </link>
  <joint
    name="rf_2_joint"
    type="continuous">
    <origin
      xyz="0.42821 -0.19269 0.030114"
      rpy="3.1416 0 0" />
    <parent
      link="base_link" />
    <child
      link="rf_2" />
    <axis
      xyz="0 0 1" />
  </joint>
  <link
    name="rf_1">
    <inertial>
      <origin
        xyz="1.5308E-10 3.0365E-11 -0.0165"
        rpy="0 0 0" />
      <mass
        value="0.084167" />
      <inertia
        ixx="0.00010416"
        ixy="8.0828E-14"
        ixz="7.7644E-14"
        iyy="0.00010416"
        iyz="2.4603E-14"
        izz="0.0002057" />
    </inertial>
    <visual>
      <origin
        xyz="0 0 0"
        rpy="0 0 0" />
      <geometry>
        <mesh
          filename="package://Wheelchair_v4/meshes/rf_1.STL" />
      </geometry>
      <material
        name="">
        <color
          rgba="0.62745 0.62745 0.62745 1" />
      </material>
    </visual>
    <collision>
      <origin
        xyz="0 0 0"
        rpy="0 0 0" />
      <geometry>
        <mesh
          filename="package://Wheelchair_v4/meshes/rf_1.STL" />
      </geometry>
    </collision>
  </link>
  <joint
    name="rf_1_joint"
    type="continuous">
    <origin
      xyz="-0.00025 -0.0165 0.070746"
      rpy="1.5708 0 0" />
    <parent
      link="rf_2" />
    <child
      link="rf_1" />
    <axis
      xyz="0 0 1" />
  </joint>
</robot>