<?xml version="1.0" encoding="utf-8"?>
<!-- This URDF was automatically created by SolidWorks to URDF Exporter! Originally created by Stephen Brawner (brawner@gmail.com) 
     Commit Version: 1.6.0-1-g15f4949  Build Version: 1.6.7594.29634
     For more information, please see http://wiki.ros.org/sw_urdf_exporter -->
<robot
  name="Wheelchair_urdf_v3">
  <link
    name="base_link">
    <inertial>
      <origin
        xyz="-0.070315 -0.0031233 0.29472"
        rpy="0 0 0" />
      <mass
        value="5.1915" />
      <inertia
        ixx="0.20197"
        ixy="5.3998E-06"
        ixz="-0.021918"
        iyy="0.21207"
        iyz="3.1856E-06"
        izz="0.20054" />
    </inertial>
    <visual>
      <origin
        xyz="0 0 0"
        rpy="0 0 0" />
      <geometry>
        <mesh
          filename="package://Wheelchair_urdf_v3/meshes/base_link.STL" />
      </geometry>
      <material
        name="">
        <color
          rgba="0.62745 0.62745 0.62745 1" />
      </material>
    </visual>
    <collision>
      <origin
        xyz="0 0 0"
        rpy="0 0 0" />
      <geometry>
        <mesh
          filename="package://Wheelchair_urdf_v3/meshes/base_link.STL" />
      </geometry>
    </collision>
  </link>
  <link
    name="lidar_l">
    <inertial>
      <origin
        xyz="0 1.1102E-16 -0.005"
        rpy="0 0 0" />
      <mass
        value="0.001131" />
      <inertia
        ixx="1.9604E-08"
        ixy="-8.8922E-24"
        ixz="-1.7937E-41"
        iyy="1.9604E-08"
        iyz="4.4116E-24"
        izz="2.0358E-08" />
    </inertial>
    <visual>
      <origin
        xyz="0 0 0"
        rpy="0 0 0" />
      <geometry>
        <mesh
          filename="package://Wheelchair_urdf_v3/meshes/lidar_l.STL" />
      </geometry>
      <material
        name="">
        <color
          rgba="0.62745 0.62745 0.62745 1" />
      </material>
    </visual>
    <collision>
      <origin
        xyz="0 0 0"
        rpy="0 0 0" />
      <geometry>
        <mesh
          filename="package://Wheelchair_urdf_v3/meshes/lidar_l.STL" />
      </geometry>
    </collision>
  </link>
  <joint
    name="lidar_l_joint"
    type="fixed">
    <origin
      xyz="0.25961 0.27982 0.18725"
      rpy="0 0 0" />
    <parent
      link="base_link" />
    <child
      link="lidar_l" />
    <axis
      xyz="0 0 0" />
  </joint>
  <link
    name="lidar_r">
    <inertial>
      <origin
        xyz="0 0 -0.005"
        rpy="0 0 0" />
      <mass
        value="0.001131" />
      <inertia
        ixx="1.9604E-08"
        ixy="8.9611E-24"
        ixz="4.8046E-40"
        iyy="1.9604E-08"
        iyz="0"
        izz="2.0358E-08" />
    </inertial>
    <visual>
      <origin
        xyz="0 0 0"
        rpy="0 0 0" />
      <geometry>
        <mesh
          filename="package://Wheelchair_urdf_v3/meshes/lidar_r.STL" />
      </geometry>
      <material
        name="">
        <color
          rgba="0.62745 0.62745 0.62745 1" />
      </material>
    </visual>
    <collision>
      <origin
        xyz="0 0 0"
        rpy="0 0 0" />
      <geometry>
        <mesh
          filename="package://Wheelchair_urdf_v3/meshes/lidar_r.STL" />
      </geometry>
    </collision>
  </link>
  <joint
    name="lidar_r_joint"
    type="fixed">
    <origin
      xyz="0.2588 -0.27693 0.18725"
      rpy="0 0 0" />
    <parent
      link="base_link" />
    <child
      link="lidar_r" />
    <axis
      xyz="0 0 0" />
  </joint>
  <link
    name="lidar_t">
    <inertial>
      <origin
        xyz="-1.7261E-06 1.2481E-06 -0.0075"
        rpy="0 0 0" />
      <mass
        value="0.0031421" />
      <inertia
        ixx="1.6826E-07"
        ixy="2.6425E-13"
        ixz="3.4624E-22"
        iyy="1.6808E-07"
        iyz="8.9002E-14"
        izz="2.1851E-07" />
    </inertial>
    <visual>
      <origin
        xyz="0 0 0"
        rpy="0 0 0" />
      <geometry>
        <mesh
          filename="package://Wheelchair_urdf_v3/meshes/lidar_t.STL" />
      </geometry>
      <material
        name="">
        <color
          rgba="0.62745 0.62745 0.62745 1" />
      </material>
    </visual>
    <collision>
      <origin
        xyz="0 0 0"
        rpy="0 0 0" />
      <geometry>
        <mesh
          filename="package://Wheelchair_urdf_v3/meshes/lidar_t.STL" />
      </geometry>
    </collision>
  </link>
  <joint
    name="lidar_t_joint"
    type="fixed">
    <origin
      xyz="-0.23192 0 0.76878"
      rpy="0 0 0" />
    <parent
      link="base_link" />
    <child
      link="lidar_t" />
    <axis
      xyz="0 0 0" />
  </joint>
  <link
    name="rb_1">
    <inertial>
      <origin
        xyz="1.9776E-09 -6.144E-10 0.030228"
        rpy="0 0 0" />
      <mass
        value="0.86161" />
      <inertia
        ixx="0.0015965"
        ixy="1.7582E-12"
        ixz="2.8243E-11"
        iyy="0.0015965"
        iyz="-1.075E-11"
        izz="0.0029109" />
    </inertial>
    <visual>
      <origin
        xyz="0 0 0"
        rpy="0 0 0" />
      <geometry>
        <mesh
          filename="package://Wheelchair_urdf_v3/meshes/rb_1.STL" />
      </geometry>
      <material
        name="">
        <color
          rgba="0.62745 0.62745 0.62745 1" />
      </material>
    </visual>
    <collision>
      <origin
        xyz="0 0 0"
        rpy="0 0 0" />
      <geometry>
        <mesh
          filename="package://Wheelchair_urdf_v3/meshes/rb_1.STL" />
      </geometry>
    </collision>
  </link>
  <joint
    name="rb_1_joint"
    type="continuous">
    <origin
      xyz="-0.25279 -0.23244 0.085117"
      rpy="-1.5708 0 0" />
    <parent
      link="base_link" />
    <child
      link="rb_1" />
    <axis
      xyz="0 0 1" />
  </joint>
  <link
    name="lb_1">
    <inertial>
      <origin
        xyz="-1.0317E-10 2.0094E-10 -0.030229"
        rpy="0 0 0" />
      <mass
        value="0.86162" />
      <inertia
        ixx="0.001596"
        ixy="7.781E-12"
        ixz="-5.1392E-13"
        iyy="0.001596"
        iyz="-2.4587E-12"
        izz="0.0029098" />
    </inertial>
    <visual>
      <origin
        xyz="0 0 0"
        rpy="0 0 0" />
      <geometry>
        <mesh
          filename="package://Wheelchair_urdf_v3/meshes/lb_1.STL" />
      </geometry>
      <material
        name="">
        <color
          rgba="0.62745 0.62745 0.62745 1" />
      </material>
    </visual>
    <collision>
      <origin
        xyz="0 0 0"
        rpy="0 0 0" />
      <geometry>
        <mesh
          filename="package://Wheelchair_urdf_v3/meshes/lb_1.STL" />
      </geometry>
    </collision>
  </link>
  <joint
    name="lb_1_joint"
    type="continuous">
    <origin
      xyz="-0.25279 0.23244 0.085117"
      rpy="-1.5708 0 0" />
    <parent
      link="base_link" />
    <child
      link="lb_1" />
    <axis
      xyz="0 0 1" />
  </joint>
  <link
    name="lf_2">
    <inertial>
      <origin
        xyz="-0.006404 0.012351 0.036333"
        rpy="0 0 0" />
      <mass
        value="0.029788" />
      <inertia
        ixx="3.6455E-05"
        ixy="4.9462E-07"
        ixz="5.4193E-06"
        iyy="3.5906E-05"
        iyz="-3.1816E-06"
        izz="7.0144E-06" />
    </inertial>
    <visual>
      <origin
        xyz="0 0 0"
        rpy="0 0 0" />
      <geometry>
        <mesh
          filename="package://Wheelchair_urdf_v3/meshes/lf_2.STL" />
      </geometry>
      <material
        name="">
        <color
          rgba="0.62745 0.62745 0.62745 1" />
      </material>
    </visual>
    <collision>
      <origin
        xyz="0 0 0"
        rpy="0 0 0" />
      <geometry>
        <mesh
          filename="package://Wheelchair_urdf_v3/meshes/lf_2.STL" />
      </geometry>
    </collision>
  </link>
  <joint
    name="lf_2_joint"
    type="continuous">
    <origin
      xyz="0.16276 0.19094 0.13325"
      rpy="3.1416 0 3.1416" />
    <parent
      link="base_link" />
    <child
      link="lf_2" />
    <axis
      xyz="0 0 1" />
  </joint>
  <link
    name="lf_1">
    <inertial>
      <origin
        xyz="1.3605E-10 -2.5313E-12 0.0165"
        rpy="0 0 0" />
      <mass
        value="0.084167" />
      <inertia
        ixx="0.00010416"
        ixy="5.6617E-15"
        ixz="5.7277E-15"
        iyy="0.00010416"
        iyz="-1.0736E-14"
        izz="0.0002057" />
    </inertial>
    <visual>
      <origin
        xyz="0 0 0"
        rpy="0 0 0" />
      <geometry>
        <mesh
          filename="package://Wheelchair_urdf_v3/meshes/lf_1.STL" />
      </geometry>
      <material
        name="">
        <color
          rgba="0.62745 0.62745 0.62745 1" />
      </material>
    </visual>
    <collision>
      <origin
        xyz="0 0 0"
        rpy="0 0 0" />
      <geometry>
        <mesh
          filename="package://Wheelchair_urdf_v3/meshes/lf_1.STL" />
      </geometry>
    </collision>
  </link>
  <joint
    name="lf_1_joint"
    type="continuous">
    <origin
      xyz="-0.0124743892795263 -0.0147500000000003 0.070745777131803"
      rpy="1.5707963267949 0 3.14159265358979" />
    <parent
      link="lf_2" />
    <child
      link="lf_1" />
    <axis
      xyz="0 0 1" />
  </joint>
  <link
    name="rf_2">
    <inertial>
      <origin
        xyz="0 0 0"
        rpy="0 0 0" />
      <mass
        value="0" />
      <inertia
        ixx="0"
        ixy="0"
        ixz="0"
        iyy="0"
        iyz="0"
        izz="0" />
    </inertial>
    <visual>
      <origin
        xyz="0 0 0"
        rpy="0 0 0" />
      <geometry>
        <mesh
          filename="package://Wheelchair_urdf_v3/meshes/rf_2.STL" />
      </geometry>
      <material
        name="">
        <color
          rgba="1 1 1 1" />
      </material>
    </visual>
    <collision>
      <origin
        xyz="0 0 0"
        rpy="0 0 0" />
      <geometry>
        <mesh
          filename="package://Wheelchair_urdf_v3/meshes/rf_2.STL" />
      </geometry>
    </collision>
  </link>
  <joint
    name="rf_2_joint"
    type="continuous">
    <origin
      xyz="0.175484096480597 -0.192692211833176 0.133245777131803"
      rpy="3.14159265358979 0 0" />
    <parent
      link="base_link" />
    <child
      link="rf_2" />
    <axis
      xyz="0 0 1" />
  </joint>
  <link
    name="rf_1">
    <inertial>
      <origin
        xyz="1.5308E-10 3.0365E-11 -0.0165"
        rpy="0 0 0" />
      <mass
        value="0.084167" />
      <inertia
        ixx="0.00010416"
        ixy="8.0828E-14"
        ixz="7.7644E-14"
        iyy="0.00010416"
        iyz="2.4603E-14"
        izz="0.0002057" />
    </inertial>
    <visual>
      <origin
        xyz="0 0 0"
        rpy="0 0 0" />
      <geometry>
        <mesh
          filename="package://Wheelchair_urdf_v3/meshes/rf_1.STL" />
      </geometry>
      <material
        name="">
        <color
          rgba="0.62745 0.62745 0.62745 1" />
      </material>
    </visual>
    <collision>
      <origin
        xyz="0 0 0"
        rpy="0 0 0" />
      <geometry>
        <mesh
          filename="package://Wheelchair_urdf_v3/meshes/rf_1.STL" />
      </geometry>
    </collision>
  </link>
  <joint
    name="rf_1_joint"
    type="continuous">
    <origin
      xyz="-0.00025 -0.0165 0.070745777131803"
      rpy="1.5707963267949 0 0" />
    <parent
      link="rf_2" />
    <child
      link="rf_1" />
    <axis
      xyz="0 0 1" />
  </joint>
</robot>